<?xml version="1.0" ?>
<robot xmlns:xacro="http://www.ros.org/wiki/xacro">

    <xacro:property name="connect_offset" value="0.02633"/>
    <xacro:property name="thigh_offset_y" value="-0.0645"/>
    <xacro:property name="thigh_offset_z" value="-0.0145"/>

    <xacro:macro name="phantomx" params="parent *origin">

        <joint name="j_phantomx_attachment" type="fixed">
            <parent link="${parent}"/>
            <child link="MP_BODY"/>
            <insert_block name="origin"/>
        </joint>

        <link name="MP_BODY">
            <inertial>
                <origin xyz="0 0 0"/>
                <mass value="0.97559947"/>
                <inertia ixx="3.1081800" ixy="-0.25460189" ixz="2.0318174" iyy="6.3787776" iyz="0.16417863"
                         izz="5.3316425"/>
            </inertial>
            <visual>
                <origin xyz="0 0 0" rpy="0 0 0"/>
                <geometry>
                    <mesh filename="package://phantomx_description/meshes/body.STL" scale="1 1 1"/>
                </geometry>
                <material name="Grey">
                    <color rgba="0.20 0.20 0.20 1.0"/>
                </material>
            </visual>
            <collision>
                <origin xyz="0 0 0" rpy="0 0 0"/>
                <geometry>
                    <mesh filename="package://phantomx_description/meshes/body_coll.STL" scale="1 1 1"/>
                </geometry>

            </collision>
        </link>

        <gazebo reference="MP_BODY">
            <material>Gazebo/Grey</material>
        </gazebo>

        <xacro:leg_l xyz="0.1248 -0.06164  0.001116" rpy="0 4.7123 0.7853981633974483" suffix="rf"/>
        <xacro:leg_l xyz="0 -0.1034  0.001116" rpy="0 4.7123 0" suffix="rm"/>
        <xacro:leg_l xyz="-0.1248 -0.06164  0.001116" rpy="0 4.7123 -0.7853981633974483" suffix="rr"/>


        <xacro:leg_l xyz="0.1248 0.06164  0.001116" rpy="0 4.7123 2.356194490192345" suffix="lf"/>
        <xacro:leg_l xyz="0 0.1034  0.001116" rpy="0 4.7123 3.14159" suffix="lm"/>
        <xacro:leg_l xyz="-0.1248 0.06164  0.001116" rpy="0 4.7123 3.9269908169872414" suffix="lr"/>

<!-- <xacro:camera2 xyz="0 -0.08164  0.142" rpy="0 0 -1.5707" suffix="right"/>
 <xacro:camera2 xyz="0 0.08164  0.142" rpy="0 0 1.5707" suffix="left"/> -->
        <!--xacro:camera2 xyz="-0.1 -0.08164  0.142" rpy="0 -0.25 -1.5707" suffix="right"/>
        <xacro:camera2 xyz="-0.1 0.08164  0.142" rpy="0 -0.25 1.5707" suffix="left"/-->
        <xacro:camera2 xyz="0.125 0  0.142" rpy="0 -0.25 0" suffix="front"/>
        <joint name="phantomx_camera_base_front" type="fixed">
            <parent link="MP_BODY"/>
            <child link="camera_base_front"/>
            <origin xyz="0.100 0 0.060" rpy="0 0 0" />
        </joint>
        <link name="camera_base_front">
            <inertial>
                <origin xyz="0 0 0" rpy="0 0 0"/>
                <mass value="0.001"/>
                <inertia ixx="0.01" ixy="0" ixz="0" iyy="0.01" iyz="0"
                    izz="0.01"/>
            </inertial>
            <collision>
                <origin xyz="0 0 0" rpy="0 0 0"/>
                <geometry>
                    <box size="0.073000 0.276000 0.072000"/>
                </geometry>
            </collision>
            <visual>
                <origin xyz="0 0 0" rpy="0 0 0"/>
                <geometry>
                    <box size="0.03 0.05 0.070 "/>
                </geometry>
            </visual>
        </link>


</xacro:macro>


<xacro:macro name="camera2" params="xyz rpy suffix">

    <joint name="phantomx_camera_${suffix}" type="fixed">
        <parent link="MP_BODY"/>
        <child link="camera_${suffix}"/>
        <origin xyz="${xyz}" rpy="${rpy}" />
    </joint>

    <link name="camera_${suffix}">
        <inertial>
            <origin xyz="0 0 0" rpy="0 0 0"/>
            <mass value="0.1"/>
            <inertia ixx="0.2" ixy="0" ixz="0" iyy="0.2" iyz="0"
                izz="0.2"/>
        </inertial>
        <collision>
            <origin xyz="0 0 0" rpy="0 0 0"/>
            <geometry>
                <box size="0.073000 0.276000 0.072000"/>
            </geometry>
        </collision>
        <visual>
            <origin xyz="0 0 0" rpy="0 0 0"/>
            <geometry>
                <!--<box size="0.073000 0.276000 0.072000"/>-->
                <mesh filename="package://phantomx_description/meshes/kinect/meshes/kinect.dae" />
            </geometry>
        </visual>
    </link>

    <gazebo reference="camera_${suffix}">
        <sensor name="camera_{suffix}" type="depth">
            <update_rate>20</update_rate>
            <camera>
                <horizontal_fov>1.047198</horizontal_fov>
                <image>
                    <width>640</width>
                    <height>480</height>
                    <format>R8G8B8</format>
                </image>
                <clip>
                    <near>0.05</near>
                    <far>10</far>
                </clip>
            </camera>


            <plugin name="camera_plugin" filename="libgazebo_ros_openni_kinect.so">
                <baseline>0.2</baseline>
                <alwaysOn>true</alwaysOn>
                <updateRate>0.0</updateRate>
                <cameraName>camera_${suffix}</cameraName>
                <imageTopicName>/phantomx/camera_${suffix}/color/image_raw</imageTopicName>
                <cameraInfoTopicName>/phantomx/camera_${suffix}/color/camera_info</cameraInfoTopicName>
                <depthImageTopicName>/phantomx/camera_${suffix}/depth/image_raw</depthImageTopicName>
                <depthImageCameraInfoTopicName>/phantomx/camera_${suffix}/depth/camera_info</depthImageCameraInfoTopicName>
                <pointCloudTopicName>/phantomx/camera_${suffix}/depth/points</pointCloudTopicName>
                <frameName>camera_${suffix}</frameName>
                <pointCloudCutoff>0.1</pointCloudCutoff>
                <pointCloudCutoffMax>10.0</pointCloudCutoffMax>
                <distortionK1>0</distortionK1>
                <distortionK2>0</distortionK2>
                <distortionK3>0</distortionK3>
                <distortionT1>0</distortionT1>
                <distortionT2>0</distortionT2>
                <CxPrime>0</CxPrime>
                <Cx>0</Cx>
                <Cy>0</Cy>
                <focalLength>0</focalLength>
                <hackBaseline>0</hackBaseline>
            </plugin>

        </sensor>
    </gazebo>
</xacro:macro>

    <xacro:macro name="leg_l" params="xyz rpy suffix">

        <link name="c1_${suffix}">
            <inertial>
                <origin xyz="0 -${connect_offset} 0" rpy="0 0 0"/>
                <mass value="0.324357719"/>
                <inertia ixx="0.0051411124" ixy="-0.00057530255" ixz="-0.000024729049" iyy="0.0081915737"
                         iyz="-0.000019223094" izz="0.0011379812"/>
            </inertial>
            <visual>
                <origin xyz="0 -0.0252 0" rpy="0 0 0"/>
                <geometry>
                    <!--box size="0.045 0.022 0.0325" /-->
                    <mesh filename="package://phantomx_description/meshes/connect.STL" scale="1 1 1"/>
                </geometry>
                <material name="Grey">
                    <color rgba="0.20 0.20 0.20 1.0"/>
                </material>
            </visual>
            <collision>
                <origin xyz="0 -${connect_offset} 0" rpy="0 0 0"/>
                <geometry>
                    <mesh filename="package://phantomx_description/meshes/connect_coll.STL" scale="1 1 1"/>
                </geometry>
            </collision>
        </link>

        <gazebo reference="c1_${suffix}">
            <dampingFactor>0.0005</dampingFactor>
        </gazebo>

        <link name="c2_${suffix}">
            <inertial>
                <origin xyz="0 -${connect_offset} 0" rpy="0 0 0"/>
                <mass value="0.324357719"/>
                <inertia ixx="0.0051411124" ixy="-0.00057530255" ixz="-0.000024729049" iyy="0.0081915737"
                         iyz="-0.000019223094" izz="0.0011379812"/>
            </inertial>
            <visual>
                <origin xyz="0 -0.0252 0" rpy="0 0 0"/>
                <geometry>
                    <!--box size="0.045 0.022 0.0325" /-->
                    <mesh filename="package://phantomx_description/meshes/connect.STL" scale="1 1 1"/>
                </geometry>
                <material name="Grey">
                    <color rgba="0.20 0.20 0.20 1.0"/>
                </material>
            </visual>
            <collision>
                <origin xyz="0 -${connect_offset} 0" rpy="0 0 0"/>
                <geometry>
                    <mesh filename="package://phantomx_description/meshes/connect_coll.STL" scale="1 1 1"/>
                </geometry>
            </collision>
        </link>

        <gazebo reference="c2_${suffix}">
            <dampingFactor>0.0005</dampingFactor>
        </gazebo>

        <link name="thigh_${suffix}">
            <inertial>
                <origin xyz="0 0 0" rpy="0 0 0"/>
                <mass value="0.324357719"/>
                <inertia ixx="0.0051411124" ixy="-0.00057530255" ixz="-0.000024729049" iyy="0.0081915737"
                         iyz="-0.000019223094" izz="0.0011379812"/>
            </inertial>
            <visual>
                <origin xyz="0 0 0" rpy="0 0 0"/>
                <geometry>
                    <mesh filename="package://phantomx_description/meshes/thigh_l.STL" scale="1 1 1"/>
                </geometry>
                <material name="Grey">
                    <color rgba="0.20 0.20 0.20 1.0"/>
                </material>
            </visual>
            <collision>
                <origin xyz="0 0 0" rpy="0 0 0"/>
                <geometry>
                    <mesh filename="package://phantomx_description/meshes/thigh_l_coll.STL" scale="1 1 1"/>
                </geometry>
            </collision>
        </link>

        <gazebo reference="thigh_${suffix}">
            <dampingFactor>0.0005</dampingFactor>
        </gazebo>

        <link name="tibia_${suffix}">
            <inertial>
                <origin xyz="0 0 0" rpy="0 0 0"/>
                <mass value="0.324357719"/>
                <inertia ixx="0.0051411124" ixy="-0.00057530255" ixz="-0.000024729049" iyy="0.0081915737"
                         iyz="-0.000019223094" izz="0.0011379812"/>
            </inertial>
            <visual>
                <origin xyz="0 0 0" rpy="0 0 0"/>
                <geometry>
                    <mesh filename="package://phantomx_description/meshes/tibia_l.STL" scale="1 1 1"/>
                </geometry>
                <material name="Grey">
                    <color rgba="0.20 0.20 0.20 1.0"/>
                </material>
            </visual>
            <collision>
                <origin xyz="0 0 0" rpy="0 0 0"/>
                <geometry>
                    <mesh filename="package://phantomx_description/meshes/tibia_l_coll.STL" scale="1 1 1"/>
                </geometry>
            </collision>
        </link>

        <gazebo reference="tibia_${suffix}">
            <mu1>50.0</mu1>
            <mu2>50.0</mu2>
            <fdir1>0.000000 0.000000 0.000000</fdir1>
            <kp>500000.0</kp>
            <kd>10.0</kd>
            <maxVel>0.00</maxVel>
            <minDepth>0.001</minDepth>
            <dampingFactor>0.0005</dampingFactor>
            <selfCollide>1</selfCollide>
        </gazebo>

        <joint name="j_c1_${suffix}" type="revolute">
            <parent link="MP_BODY"/>
            <child link="c1_${suffix}"/>
            <origin xyz="${xyz}" rpy="${rpy}"/>
            <axis xyz="1 0 0"/>
            <limit effort="2.8" velocity="5.6548668" lower="-2.6179939" upper="2.6179939"/>
        </joint>

        <joint name="j_c2_${suffix}" type="fixed">
            <parent link="c1_${suffix}"/>
            <child link="c2_${suffix}"/>
            <origin xyz="0 -0.054 0" rpy="0 1.5704 3.14159"/>
        </joint>

        <joint name="j_thigh_${suffix}" type="revolute">
            <parent link="c2_${suffix}"/>
            <child link="thigh_${suffix}"/>
            <origin xyz="0 0 0" rpy=" 0 3.14159 3.14159"/>
            <axis xyz="1 0 0"/>
            <limit effort="2.8" velocity="5.6548668" lower="-2.6179939" upper="2.6179939"/>
        </joint>

        <joint name="j_tibia_${suffix}" type="revolute">
            <parent link="thigh_${suffix}"/>
            <child link="tibia_${suffix}"/>
            <origin xyz="0 ${thigh_offset_y} ${thigh_offset_z}" rpy="-1.5707 0 3.14159"/>
            <axis xyz="1 0 0"/>
            <limit effort="2.8" velocity="5.6548668" lower="-2.6179939" upper="2.6179939"/>
        </joint>

        <transmission name="t_c1_${suffix}">
            <type>transmission_interface/SimpleTransmission</type>
            <joint name="j_c1_${suffix}">
                <hardwareInterface>hardware_interface/EffortJointInterface</hardwareInterface>
            </joint>
            <actuator name="m_c1_${suffix}">
                <hardwareInterface>hardware_interface/EffortJointInterface</hardwareInterface>
                <mechanicalReduction>1</mechanicalReduction>
            </actuator>
        </transmission>

        <transmission name="t_thigh_${suffix}">
            <type>transmission_interface/SimpleTransmission</type>
            <joint name="j_thigh_${suffix}">
                <hardwareInterface>hardware_interface/EffortJointInterface</hardwareInterface>
            </joint>
            <actuator name="m_thigh_${suffix}">
                <hardwareInterface>hardware_interface/EffortJointInterface</hardwareInterface>
                <mechanicalReduction>1</mechanicalReduction>
            </actuator>
        </transmission>

        <transmission name="t_tibia_${suffix}">
            <type>transmission_interface/SimpleTransmission</type>
            <joint name="j_tibia_${suffix}">
                <hardwareInterface>hardware_interface/EffortJointInterface</hardwareInterface>
            </joint>
            <actuator name="m_tibia_${suffix}">
                <hardwareInterface>hardware_interface/EffortJointInterface</hardwareInterface>
                <mechanicalReduction>1</mechanicalReduction>
            </actuator>
        </transmission>

        <gazebo reference="c1_${suffix}">
            <material>Gazebo/Grey</material>
        </gazebo>

        <gazebo reference="c2_${suffix}">
            <material>Gazebo/Grey</material>
        </gazebo>

        <gazebo reference="thigh_${suffix}">
            <material>Gazebo/Grey</material>
        </gazebo>

        <gazebo reference="tibia_${suffix}">
            <material>Gazebo/Grey</material>
        </gazebo>

    </xacro:macro>

    <joint name="body_to_imu_joint" type="fixed">
      <origin xyz="0.0 0.0 -0.025" rpy="0 0 0"/>
      <parent link="MP_BODY"/>
      <child link="imu_link"/>
    </joint>

    <link name="imu_link">
      <inertial>
        <origin xyz="0.0 0.0 0.00" rpy="0.0 0.0 0.0"/>
        <mass value="0.05"/>
        <inertia ixx="0.01" ixy="0" ixz="0" iyy="0.01" iyz="0" izz="0.01"/>
      </inertial>
      <visual>
        <origin xyz="0.0 0.0 0.00" rpy="0 0 0"/>
        <geometry>
          <cylinder radius="0.02" length="0.02"/>
        </geometry>
        <material name="Cyan">
          <color rgba="0 1.0 1.0 1.0"/>
        </material>
      </visual>
      <collision name = "imu_coll">
        <origin xyz="0.0 0.0 0.00" rpy="0 0 0"/>
        <geometry>
          <cylinder radius="0.02" length="0.02"/>
        </geometry>
      </collision>
    </link>

    <gazebo reference="imu_link">
      <gravity>true</gravity>
      <sensor name="imu_sensor" type="imu">
        <always_on>true</always_on>
        <update_rate>100</update_rate>
        <visualize>true</visualize>
        <plugin filename="libgazebo_ros_imu_sensor.so" name="imu_plugin">
          <topicName>phantomx/imu</topicName>
          <bodyName>imu_link</bodyName>
          <updateRateHZ>10.0</updateRateHZ>
          <gaussianNoise>0.0</gaussianNoise>
          <xyzOffset>0 0 0</xyzOffset>
          <rpyOffset>0 0 0</rpyOffset>
          <frameName>imu_link1</frameName>
        </plugin>
        <pose>0 0 0 0 0 0</pose>
      </sensor>
    </gazebo>




    <joint name="car_to_lidar_joint" type="fixed">
        <origin xyz="0.0 0.0 0.0685" rpy="0 0 0"/>
        <parent link="MP_BODY"/>
        <child link="lidar_link"/>


    </joint>

    <link name="lidar_link">
        <inertial>
            <origin xyz="0.0 0.0 -0.01" rpy="0.0 0.0 0.0"/>
            <mass value="0.05"/>
            <inertia ixx="0.01" ixy="0" ixz="0" iyy="0.01" iyz="0" izz="0.01"/>
        </inertial>
        <visual>
            <origin xyz="0.0 0.0 -0.01" rpy="0 0 0"/>
            <geometry>
                <cylinder radius="0.005" length="0.072"/>
            </geometry>
            <material name="Grey">
                <color rgba="0.20 0.20 0.20 1.0"/>
            </material>
        </visual>
        <collision name = "lidar_coll">
            <origin xyz="0.0 0.0 -0.01" rpy="0 0 0"/>
            <geometry>
                <cylinder radius="0.005" length="0.072"/>
            </geometry>
        </collision>
    </link>


    <joint name="car_to_light_joint" type="fixed">
        <origin xyz="0.0 0.0 0.0" rpy="0 0 0"/>
        <parent link="MP_BODY"/>
        <child link="light_link"/>
    </joint>

    <link name="light_link">
    </link>

    <gazebo reference="light_link">
        <light name='light_source_front' type='spot'>
            <pose frame=''>0.1 0 0.03 0 -2. 0</pose>
            <id>light_source</id>
            <attenuation>
                <range>30</range>
                <linear>0.005</linear>
            </attenuation>
            <diffuse>1 1 1 1</diffuse>
            <specular>1 0 0 1</specular>
            <spot>
                <inner_angle>1</inner_angle>
                <outer_angle>2</outer_angle>
                <falloff>1</falloff>
            </spot>
            <direction>0 0 -1</direction>
        </light>
        <plugin name='light_control' filename='libFlashLightPlugin.so'>
            <enable>true</enable>
           <light>
                <id>cylinder/light_source_front</id>
                <duration>1</duration>
                <interval>0</interval>
                <color>1 1 1</color>
            </light>
        </plugin>
        <selfCollide>false</selfCollide>
    </gazebo>


      <gazebo reference="lidar_link">
        <sensor type="ray" name="lidar">
          <visualize>false</visualize>
          <update_rate>5</update_rate>
          <ray>
            <scan>
              <horizontal>
                <samples>720</samples>
                <resolution>1</resolution>
                <min_angle>-1.57</min_angle>
                <max_angle>1.57</max_angle>
              </horizontal>
            </scan>
            <range>
              <min>0.20</min>
              <max>15.0</max>
              <resolution>0.01</resolution>
            </range>
            <noise>
              <type>gaussian</type>
              <mean>0.0</mean>
              <stddev>0.01</stddev>
            </noise>
          </ray>
          <plugin name="lidar_controller" filename="libgazebo_ros_laser.so">
            <topicName>/phantomx/lidar</topicName>
            <frameName>lidar_link</frameName>
          </plugin>
        </sensor>
      </gazebo>

</robot>
